2024-03-06 19:57:26,410 - Traceback (most recent call last):
  File "/usr/local/lib/python3.10/site-packages/django/contrib/sessions/backends/base.py", line 187, in _get_session
    return self._session_cache
AttributeError: 'SessionStore' object has no attribute '_session_cache'

During handling of the above exception, another exception occurred:

Traceback (most recent call last):
  File "/usr/local/lib/python3.10/site-packages/django/db/backends/utils.py", line 105, in _execute
    return self.cursor.execute(sql, params)
psycopg2.errors.UndefinedTable: relation "django_session" does not exist
LINE 1: ...ession_data", "django_session"."expire_date" FROM "django_se...
                                                             ^


The above exception was the direct cause of the following exception:

Traceback (most recent call last):
  File "/usr/local/lib/python3.10/site-packages/django/core/handlers/base.py", line 197, in _get_response
    response = wrapped_callback(request, *callback_args, **callback_kwargs)
  File "/usr/local/lib/python3.10/site-packages/django/contrib/admin/options.py", line 716, in wrapper
    return self.admin_site.admin_view(view)(*args, **kwargs)
  File "/usr/local/lib/python3.10/site-packages/django/utils/decorators.py", line 188, in _view_wrapper
    result = _process_exception(request, e)
  File "/usr/local/lib/python3.10/site-packages/django/utils/decorators.py", line 186, in _view_wrapper
    response = view_func(request, *args, **kwargs)
  File "/usr/local/lib/python3.10/site-packages/django/views/decorators/cache.py", line 80, in _view_wrapper
    response = view_func(request, *args, **kwargs)
  File "/usr/local/lib/python3.10/site-packages/django/contrib/admin/sites.py", line 228, in inner
    if not self.has_permission(request):
  File "/usr/local/lib/python3.10/site-packages/django/contrib/admin/sites.py", line 201, in has_permission
    return request.user.is_active and request.user.is_staff
  File "/usr/local/lib/python3.10/site-packages/django/utils/functional.py", line 251, in inner
    self._setup()
  File "/usr/local/lib/python3.10/site-packages/django/utils/functional.py", line 404, in _setup
    self._wrapped = self._setupfunc()
  File "/usr/local/lib/python3.10/site-packages/django/contrib/auth/middleware.py", line 33, in <lambda>
    request.user = SimpleLazyObject(lambda: get_user(request))
  File "/usr/local/lib/python3.10/site-packages/django/contrib/auth/middleware.py", line 13, in get_user
    request._cached_user = auth.get_user(request)
  File "/usr/local/lib/python3.10/site-packages/django/contrib/auth/__init__.py", line 209, in get_user
    user_id = _get_user_session_key(request)
  File "/usr/local/lib/python3.10/site-packages/django/contrib/auth/__init__.py", line 62, in _get_user_session_key
    return get_user_model()._meta.pk.to_python(request.session[SESSION_KEY])
  File "/usr/local/lib/python3.10/site-packages/django/contrib/sessions/backends/base.py", line 53, in __getitem__
    return self._session[key]
  File "/usr/local/lib/python3.10/site-packages/django/contrib/sessions/backends/base.py", line 192, in _get_session
    self._session_cache = self.load()
  File "/usr/local/lib/python3.10/site-packages/django/contrib/sessions/backends/db.py", line 42, in load
    s = self._get_session_from_db()
  File "/usr/local/lib/python3.10/site-packages/django/contrib/sessions/backends/db.py", line 32, in _get_session_from_db
    return self.model.objects.get(
  File "/usr/local/lib/python3.10/site-packages/django/db/models/manager.py", line 87, in manager_method
    return getattr(self.get_queryset(), name)(*args, **kwargs)
  File "/usr/local/lib/python3.10/site-packages/django/db/models/query.py", line 645, in get
    num = len(clone)
  File "/usr/local/lib/python3.10/site-packages/django/db/models/query.py", line 382, in __len__
    self._fetch_all()
  File "/usr/local/lib/python3.10/site-packages/django/db/models/query.py", line 1928, in _fetch_all
    self._result_cache = list(self._iterable_class(self))
  File "/usr/local/lib/python3.10/site-packages/django/db/models/query.py", line 91, in __iter__
    results = compiler.execute_sql(
  File "/usr/local/lib/python3.10/site-packages/django/db/models/sql/compiler.py", line 1562, in execute_sql
    cursor.execute(sql, params)
  File "/usr/local/lib/python3.10/site-packages/django/db/backends/utils.py", line 122, in execute
    return super().execute(sql, params)
  File "/usr/local/lib/python3.10/site-packages/django/db/backends/utils.py", line 79, in execute
    return self._execute_with_wrappers(
  File "/usr/local/lib/python3.10/site-packages/django/db/backends/utils.py", line 92, in _execute_with_wrappers
    return executor(sql, params, many, context)
  File "/usr/local/lib/python3.10/site-packages/django/db/backends/utils.py", line 100, in _execute
    with self.db.wrap_database_errors:
  File "/usr/local/lib/python3.10/site-packages/django/db/utils.py", line 91, in __exit__
    raise dj_exc_value.with_traceback(traceback) from exc_value
  File "/usr/local/lib/python3.10/site-packages/django/db/backends/utils.py", line 105, in _execute
    return self.cursor.execute(sql, params)
django.db.utils.ProgrammingError: relation "django_session" does not exist
LINE 1: ...ession_data", "django_session"."expire_date" FROM "django_se...
                                                             ^


2024-03-06 20:58:57,800 - Traceback (most recent call last):
  File "/home/roman/PycharmProjects/market/web-marketplace/.venv/lib/python3.10/site-packages/django/db/backends/utils.py", line 105, in _execute
    return self.cursor.execute(sql, params)
psycopg2.errors.NotNullViolation: null value in column "telegram_has" of relation "broadcasts" violates not-null constraint
DETAIL:  Failing row contains (1, Hi there!, , null, f, 2024-03-06 20:59:50).


The above exception was the direct cause of the following exception:

Traceback (most recent call last):
  File "/home/roman/PycharmProjects/market/web-marketplace/.venv/lib/python3.10/site-packages/django/core/handlers/base.py", line 197, in _get_response
    response = wrapped_callback(request, *callback_args, **callback_kwargs)
  File "/home/roman/PycharmProjects/market/web-marketplace/.venv/lib/python3.10/site-packages/django/contrib/admin/options.py", line 716, in wrapper
    return self.admin_site.admin_view(view)(*args, **kwargs)
  File "/home/roman/PycharmProjects/market/web-marketplace/.venv/lib/python3.10/site-packages/django/utils/decorators.py", line 188, in _view_wrapper
    result = _process_exception(request, e)
  File "/home/roman/PycharmProjects/market/web-marketplace/.venv/lib/python3.10/site-packages/django/utils/decorators.py", line 186, in _view_wrapper
    response = view_func(request, *args, **kwargs)
  File "/home/roman/PycharmProjects/market/web-marketplace/.venv/lib/python3.10/site-packages/django/views/decorators/cache.py", line 80, in _view_wrapper
    response = view_func(request, *args, **kwargs)
  File "/home/roman/PycharmProjects/market/web-marketplace/.venv/lib/python3.10/site-packages/django/contrib/admin/sites.py", line 240, in inner
    return view(request, *args, **kwargs)
  File "/home/roman/PycharmProjects/market/web-marketplace/.venv/lib/python3.10/site-packages/django/contrib/admin/options.py", line 1945, in add_view
    return self.changeform_view(request, None, form_url, extra_context)
  File "/home/roman/PycharmProjects/market/web-marketplace/.venv/lib/python3.10/site-packages/django/utils/decorators.py", line 48, in _wrapper
    return bound_method(*args, **kwargs)
  File "/home/roman/PycharmProjects/market/web-marketplace/.venv/lib/python3.10/site-packages/django/utils/decorators.py", line 188, in _view_wrapper
    result = _process_exception(request, e)
  File "/home/roman/PycharmProjects/market/web-marketplace/.venv/lib/python3.10/site-packages/django/utils/decorators.py", line 186, in _view_wrapper
    response = view_func(request, *args, **kwargs)
  File "/home/roman/PycharmProjects/market/web-marketplace/.venv/lib/python3.10/site-packages/django/contrib/admin/options.py", line 1804, in changeform_view
    return self._changeform_view(request, object_id, form_url, extra_context)
  File "/home/roman/PycharmProjects/market/web-marketplace/.venv/lib/python3.10/site-packages/django/contrib/admin/options.py", line 1855, in _changeform_view
    self.save_model(request, new_object, form, not add)
  File "/home/roman/PycharmProjects/market/web-marketplace/.venv/lib/python3.10/site-packages/django/contrib/admin/options.py", line 1259, in save_model
    obj.save()
  File "/home/roman/PycharmProjects/market/web-marketplace/.venv/lib/python3.10/site-packages/django/db/models/base.py", line 822, in save
    self.save_base(
  File "/home/roman/PycharmProjects/market/web-marketplace/.venv/lib/python3.10/site-packages/django/db/models/base.py", line 909, in save_base
    updated = self._save_table(
  File "/home/roman/PycharmProjects/market/web-marketplace/.venv/lib/python3.10/site-packages/django/db/models/base.py", line 1067, in _save_table
    results = self._do_insert(
  File "/home/roman/PycharmProjects/market/web-marketplace/.venv/lib/python3.10/site-packages/django/db/models/base.py", line 1108, in _do_insert
    return manager._insert(
  File "/home/roman/PycharmProjects/market/web-marketplace/.venv/lib/python3.10/site-packages/django/db/models/manager.py", line 87, in manager_method
    return getattr(self.get_queryset(), name)(*args, **kwargs)
  File "/home/roman/PycharmProjects/market/web-marketplace/.venv/lib/python3.10/site-packages/django/db/models/query.py", line 1847, in _insert
    return query.get_compiler(using=using).execute_sql(returning_fields)
  File "/home/roman/PycharmProjects/market/web-marketplace/.venv/lib/python3.10/site-packages/django/db/models/sql/compiler.py", line 1823, in execute_sql
    cursor.execute(sql, params)
  File "/home/roman/PycharmProjects/market/web-marketplace/.venv/lib/python3.10/site-packages/django/db/backends/utils.py", line 122, in execute
    return super().execute(sql, params)
  File "/home/roman/PycharmProjects/market/web-marketplace/.venv/lib/python3.10/site-packages/django/db/backends/utils.py", line 79, in execute
    return self._execute_with_wrappers(
  File "/home/roman/PycharmProjects/market/web-marketplace/.venv/lib/python3.10/site-packages/django/db/backends/utils.py", line 92, in _execute_with_wrappers
    return executor(sql, params, many, context)
  File "/home/roman/PycharmProjects/market/web-marketplace/.venv/lib/python3.10/site-packages/django/db/backends/utils.py", line 100, in _execute
    with self.db.wrap_database_errors:
  File "/home/roman/PycharmProjects/market/web-marketplace/.venv/lib/python3.10/site-packages/django/db/utils.py", line 91, in __exit__
    raise dj_exc_value.with_traceback(traceback) from exc_value
  File "/home/roman/PycharmProjects/market/web-marketplace/.venv/lib/python3.10/site-packages/django/db/backends/utils.py", line 105, in _execute
    return self.cursor.execute(sql, params)
django.db.utils.IntegrityError: null value in column "telegram_has" of relation "broadcasts" violates not-null constraint
DETAIL:  Failing row contains (1, Hi there!, , null, f, 2024-03-06 20:59:50).


